<mujoco model="nugus">
<compiler angle="radian" meshdir=""/>
  
  <option iterations="3" ls_iterations="5" timestep=".002">
    <flag eulerdamp="disable"/>
  </option>

  <custom>
    <numeric data="8" name="max_contact_points"/>
    <numeric data="8" name="max_geom_pairs"/>
  </custom>

  <asset>
    <mesh name="torso_visual" file="torso_visual.stl"/>
    <mesh name="left_hip_yaw_visual" file="left_hip_yaw_visual.stl"/>
    <mesh name="left_hip_roll_visual" file="left_hip_roll_visual.stl"/>
    <mesh name="left_upper_leg_visual" file="left_upper_leg_visual.stl"/>
    <mesh name="left_lower_leg_visual" file="left_lower_leg_visual.stl"/>
    <mesh name="left_ankle_visual" file="left_ankle_visual.stl"/>
    <mesh name="left_foot_visual" file="left_foot_visual.stl"/>
    <mesh name="right_hip_yaw_visual" file="right_hip_yaw_visual.stl"/>
    <mesh name="right_hip_roll_visual" file="right_hip_roll_visual.stl"/>
    <mesh name="right_upper_leg_visual" file="right_upper_leg_visual.stl"/>
    <mesh name="right_lower_leg_visual" file="right_lower_leg_visual.stl"/>
    <mesh name="right_ankle_visual" file="right_ankle_visual.stl"/>
    <mesh name="right_foot_visual" file="right_foot_visual.stl"/>
    <mesh name="right_foot_base_visual" file="right_foot_base_visual.stl"/>
    <mesh name="neck_visual" file="neck_visual.stl"/>
    <mesh name="head_visual" file="head_visual.stl"/>
    <mesh name="right_camera_visual" file="right_camera_visual.stl"/>
    <mesh name="left_shoulder_visual" file="left_shoulder_visual.stl"/>
    <mesh name="left_upper_arm_visual" file="left_upper_arm_visual.stl"/>
    <mesh name="left_lower_arm_visual" file="left_lower_arm_visual.stl"/>
    <mesh name="right_shoulder_visual" file="right_shoulder_visual.stl"/>
    <mesh name="right_upper_arm_visual" file="right_upper_arm_visual.stl"/>
    <mesh name="right_lower_arm_visual" file="right_lower_arm_visual.stl"/>
  </asset>

  <default>
    <joint damping="1.084" armature="0.045" frictionloss="0.03"/>
    <position kp="40.1" ctrlrange="-3.141592 3.141592" forcerange="-100 100"/>
    <geom contype="0" conaffinity="0" condim="1" solref="0.005 1"/>
    <site group="5" type="sphere"/>
    <default class="collision">
      <geom group="3"/>
      <default class="foot">
        <geom mass="0" type="sphere" contype="0" conaffinity="1" friction="1.0" size="0.02" group="1" rgba="1 0 0 1"/>
      </default>
    </default>
    <default class="visual">
      <geom contype="0" conaffinity="0" group="1" rgba="0.286275 0.286275 0.286275 1"/>
    </default>
    <default class="MX106">
      <joint armature="0.0266" damping="1.6548" frictionloss="0.10352"/>
      <position kp="56.052" forcerange="-11.086 11.086"/>
    </default>
    <default class="MX64">
      <joint armature="0.01195" damping="0.6782" frictionloss="0.09039"/>
      <position kp="31.1558" forcerange="-6.1621 6.1621"/>
    </default>
    <default class="XH540-W270">
      <joint armature="0.0266" damping="1.6548" frictionloss="0.10352"/>
      <position kp="56.052" forcerange="-11.086 11.086"/>
    </default>
  </default>

  <actuator>
    <position joint="left_hip_yaw" name="left_hip_yaw"/>
    <position joint="left_hip_roll" name="left_hip_roll"/>
    <position joint="left_hip_pitch" name="left_hip_pitch"/>
    <position joint="left_knee_pitch" name="left_knee_pitch"/>
    <position joint="left_ankle_pitch" name="left_ankle_pitch"/>
    <position joint="left_ankle_roll" name="left_ankle_roll"/>

    <position joint="right_hip_yaw" name="right_hip_yaw"/>
    <position joint="right_hip_roll" name="right_hip_roll"/>
    <position joint="right_hip_pitch" name="right_hip_pitch"/>
    <position joint="right_knee_pitch" name="right_knee_pitch"/>
    <position joint="right_ankle_pitch" name="right_ankle_pitch"/>
    <position joint="right_ankle_roll" name="right_ankle_roll"/>

    <position joint="neck_yaw" name="neck_yaw"/>
    <position joint="head_pitch" name="head_pitch"/>

    <position joint="left_shoulder_pitch" name="left_shoulder_pitch"/>
    <position joint="left_shoulder_roll" name="left_shoulder_roll"/>
    <position joint="left_elbow_pitch" name="left_elbow_pitch"/>
    <position joint="right_shoulder_pitch" name="right_shoulder_pitch"/>
    <position joint="right_shoulder_roll" name="right_shoulder_roll"/>
    <position joint="right_elbow_pitch" name="right_elbow_pitch"/>
  </actuator>

  <sensor>
    <framepos objtype="site" objname="imu" name="position"/>
    <gyro site="imu" name="gyro"/>
    <velocimeter site="imu" name="local_linvel"/>
    <accelerometer site="imu" name="accelerometer"/>
    <framezaxis objtype="site" objname="imu" name="upvector"/>
    <framexaxis objtype="site" objname="imu" name="forwardvector"/>
    <framelinvel objtype="site" objname="imu" name="global_linvel"/>
    <frameangvel objtype="site" objname="imu" name="global_angvel"/>
    <framequat objtype="site" objname="imu" name="orientation"/>

    <!-- Feet velocity sensors (global). -->
    <framelinvel objtype="site" objname="left_foot" name="left_foot_global_linvel"/>
    <framelinvel objtype="site" objname="right_foot" name="right_foot_global_linvel"/>

    <!-- Foot force sensors. -->
    <force site="left_foot" name="left_foot_force"/>
    <force site="right_foot" name="right_foot_force"/>
  </sensor>

  <worldbody>
    <body name="torso">
      <inertial pos="-0.000971341 -7.63301e-05 0.0898493" quat="0.998034 0.00199235 0.0599357 0.0182343" mass="1.83264" diaginertia="0.0156368 0.0131516 0.00578565"/>
      <joint name="torso_free_joint" type="free"/>
      <camera name="track" pos="0.805 -1.105 0.2" xyaxes="0.814 0.580 0.000 -0.140 0.196 0.971" mode="trackcom"/>
      <site name='imu' size='0.01' pos='0 0 0'/>
      <geom type="mesh" contype="0" conaffinity="0" group="1" density="0" rgba="0.286275 0.286275 0.286275 1" mesh="torso_visual"/>
      <geom size="0.0697546 0.0949914 0.130902" pos="-0.00200103 -1.04979e-05 0.108568" type="box" rgba="0.286275 0.286275 0.286275 0"/>
      <body name="left_hip_yaw" pos="0 0.055 0" quat="1 0 0 0">
        <inertial pos="-0.0021828 -0.00894798 -0.0247563" quat="0.706738 0.705731 0.0325035 -0.0375176" mass="0.0594023" diaginertia="0.00011878 0.000103492 5.24089e-05"/>
        <joint name="left_hip_yaw" pos="0 0 0" axis="0 0 1" limited="true" range="-3.14159 3.14159" class="MX106"/>
        <geom type="mesh" contype="0" conaffinity="0" group="1" density="0" rgba="0.286275 0.286275 0.286275 1" mesh="left_hip_yaw_visual"/>
        <geom size="0.05425 0.0470128 0.03675" pos="0 -0.00723724 -0.03675" type="box" rgba="0.286275 0.286275 0.286275 0"/>
        <body name="left_hip_roll" pos="0.0221332 0 -0.0545" quat="0.707105 0 0.707108 0">
          <inertial pos="0.015733 -0.000686158 -0.0217073" quat="0.70707 0.00800622 -0.00800603 0.707053" mass="0.395953" diaginertia="0.000375935 0.000314298 0.000127658"/>
          <joint name="left_hip_roll" pos="0 0 0" axis="0 0 1" limited="true" range="-3.14159 3.14159"/>
          <geom type="mesh" contype="0" conaffinity="0" group="1" density="0" rgba="0.286275 0.286275 0.286275 1" mesh="left_hip_roll_visual"/>
          <geom size="0.0362265 0.02765 0.046925" pos="0.0211382 0.00135 -0.026825" type="box" rgba="0.286275 0.286275 0.286275 0"/>
          <body name="left_upper_leg" pos="0 0 0" quat="0.707105 -0.707108 0 0">
            <inertial pos="0.144296 0.0401097 0.000258488" quat="0.48018 0.474915 0.52246 0.520498" mass="0.313357" diaginertia="0.00167304 0.00160068 0.000213115"/>
            <joint name="left_hip_pitch" pos="0 0 0" axis="0 0 1" limited="true" range="-3.14159 3.14159"/>
            <geom type="mesh" contype="0" conaffinity="0" group="1" density="0" rgba="0.286275 0.286275 0.286275 1" mesh="left_upper_leg_visual"/>
            <geom size="0.123135 0.0467353 0.0365" pos="0.103064 0.0303674 0" type="box" rgba="0.286275 0.286275 0.286275 0"/>
            <body name="left_lower_leg" pos="0.206046 0.0569501 0" quat="1 0 0 0">
              <inertial pos="0.1001 0.00388186 -1.61259e-08" quat="0.500001 0.500001 0.499999 0.499999" mass="0.0893011" diaginertia="0.000408951 0.0003363 9.01254e-05"/>
              <joint name="left_knee_pitch" pos="0 0 0" axis="0 0 1" limited="true" range="-3.14159 3.14159" class="XH540-W270"/>
              <geom type="mesh" contype="0" conaffinity="0" group="1" density="0" rgba="0.286275 0.286275 0.286275 1" mesh="left_lower_leg_visual"/>
              <geom size="0.114601 0.0155 0.039" pos="0.100101 0.001 0" type="box" rgba="0.286275 0.286275 0.286275 0"/>
              <body name="left_ankle" pos="0.200203 0 0" quat="1 0 0 0">
                <inertial pos="-0.015733 0.0219762 0.000512596" quat="0.508721 0.491668 -0.491137 0.508184" mass="0.329993" diaginertia="0.000265803 0.000265762 0.000157721"/>
                <joint name="left_ankle_pitch" pos="0 0 0" axis="0 0 1" limited="true" range="-3.14159 3.14159"/>
                <geom type="mesh" contype="0" conaffinity="0" group="1" density="0" rgba="0.286275 0.286275 0.286275 1" mesh="left_ankle_visual"/>
                <geom size="0.0331382 0.047194 0.02765" pos="-0.01805 0.027094 -0.00166756" type="box" rgba="0.286275 0.286275 0.286275 0"/>
                <body name="left_foot" pos="0 0 0" quat="0.707105 0.707108 0 0">
                  <inertial pos="0.0248226 0.00798542 0.033284" quat="0.99979 -0.0089131 -9.26048e-05 -0.0184639" mass="0.245581" diaginertia="0.00134758 0.00108371 0.00033179"/>
                  <joint name="left_ankle_roll" pos="0 0 0" axis="0 0 1" limited="true" range="-3.14159 3.14159"/>
                  <geom type="mesh" contype="0" conaffinity="0" group="1" density="0" rgba="0.286275 0.286275 0.286275 1" mesh="left_foot_visual"/>
                  <geom name="l_foot1" class="foot" pos="0.0379995 -0.0548465 -0.0867505"/>
                  <geom name="l_foot2" class="foot" pos="0.0379995 0.0767345 -0.0867505"/>
                  <geom name="l_foot3" class="foot" pos="0.0379995 0.0767345 0.129071"/>
                  <geom name="l_foot4" class="foot" pos="0.0379995 -0.0548465 0.129071"/>
                  <site name="left_foot" rgba="1 0 0 1" pos="0.035 0 0" euler="0 -1.571 0" size="0.01" group="1"/>
                </body>
              </body>
            </body>
          </body>
        </body>
      </body>
      <body name="right_hip_yaw" pos="0 -0.055 0" quat="1 0 0 0">
        <inertial pos="-0.00218277 0.0089479 -0.0247564" quat="0.705733 0.706736 0.0375273 -0.0325114" mass="0.0594022" diaginertia="0.000118779 0.000103492 5.24082e-05"/>
        <joint name="right_hip_yaw" pos="0 0 0" axis="0 0 1" limited="true" range="-3.14159 3.14159" class="MX106"/>
        <geom type="mesh" contype="0" conaffinity="0" group="1" density="0" rgba="0.286275 0.286275 0.286275 1" mesh="right_hip_yaw_visual"/>
        <geom size="0.05425 0.0470128 0.03675" pos="0 0.00723724 -0.03675" type="box" rgba="0.286275 0.286275 0.286275 0"/>
        <body name="right_hip_roll" pos="0.0221332 0 -0.0545" quat="0.707105 0 0.707108 0">
          <inertial pos="0.015733 -0.000232251 -0.0218286" quat="0.707049 0.00279235 -0.00279276 0.707153" mass="0.395953" diaginertia="0.000378041 0.000316367 0.000127621"/>
          <joint name="right_hip_roll" pos="0 0 0" axis="0 0 1" limited="true" range="-3.14159 3.14159"/>
          <geom type="mesh" contype="0" conaffinity="0" group="1" density="0" rgba="0.286275 0.286275 0.286275 1" mesh="right_hip_roll_visual"/>
          <geom size="0.0331382 0.02765 0.04705" pos="0.01805 -0.00315 -0.02695" type="box" rgba="0.286275 0.286275 0.286275 0"/>
          <body name="right_upper_leg" pos="0 0 0" quat="0.707105 -0.707108 0 0">
            <inertial pos="0.144343 0.0400917 -0.000278506" quat="0.47021 0.473824 0.526501 0.526488" mass="0.313809" diaginertia="0.00167983 0.00160132 0.000207139"/>
            <joint name="right_hip_pitch" pos="0 0 0" axis="0 0 1" limited="true" range="-3.14159 3.14159"/>
            <geom type="mesh" contype="0" conaffinity="0" group="1" density="0" rgba="0.286275 0.286275 0.286275 1" mesh="right_upper_leg_visual"/>
            <geom size="0.123135 0.0467353 0.0365" pos="0.103064 0.0303674 -1.86265e-09" type="box" rgba="0.286275 0.286275 0.286275 0"/>
            <body name="right_lower_leg" pos="0.206046 0.0569501 0" quat="1 0 0 0">
              <inertial pos="0.100103 0.00388186 1.61259e-08" quat="0.499999 0.499999 0.500001 0.500001" mass="0.0893011" diaginertia="0.000408951 0.0003363 9.01254e-05"/>
              <joint name="right_knee_pitch" pos="0 0 0" axis="0 0 1" limited="true" range="-3.14159 3.14159" class="XH540-W270"/>
              <geom type="mesh" contype="0" conaffinity="0" group="1" density="0" rgba="0.286275 0.286275 0.286275 1" mesh="right_lower_leg_visual"/>
              <geom size="0.114601 0.0155 0.039" pos="0.100101 0.001 0" type="box" rgba="0.286275 0.286275 0.286275 0"/>
              <body name="right_ankle" pos="0.200203 0 0" quat="1 0 0 0">
                <inertial pos="-0.015733 0.0218226 0.000508968" quat="0.51022 0.492773 -0.489643 0.507051" mass="0.329993" diaginertia="0.00026369 0.000263648 0.000157719"/>
                <joint name="right_ankle_pitch" pos="0 0 0" axis="0 0 1" limited="false"/>
                <geom type="mesh" contype="0" conaffinity="0" group="1" density="0" rgba="0.286275 0.286275 0.286275 1" mesh="right_ankle_visual"/>
                <geom size="0.0328441 0.047044 0.02765" pos="-0.0177559 0.026944 -0.00166756" type="box" rgba="0.286275 0.286275 0.286275 0"/>
                <body name="right_foot" pos="0 0 0" quat="0.707105 0.707108 0 0">
                  <inertial pos="0.024823 -0.00798676 0.0332808" quat="0.99979 0.0089119 -9.00788e-05 0.0184638" mass="0.245567" diaginertia="0.00134748 0.00108364 0.000331758"/>
                  <joint name="right_ankle_roll" pos="0 0 0" axis="0 0 1" limited="true" range="-3.14159 3.14159"/>
                  <geom type="mesh" contype="0" conaffinity="0" group="1" density="0" rgba="0.286275 0.286275 0.286275 1" mesh="right_foot_visual"/>
                  <geom size="0.0284933 0.0657897 0.107911" pos="0.00950672 -0.0109447 0.0211599" type="box" rgba="0.286275 0.286275 0.286275 0"/>
                  <geom pos="0.038 0 0" quat="0.707105 0 -0.707108 0" type="mesh" contype="0" conaffinity="0" group="1" density="0" rgba="0.615686 0.811765 0.929412 1" mesh="right_foot_base_visual"/>
                  <geom name="r_foot1" class="foot" pos="0.0379995 -0.0767345 -0.0867505"/>
                  <geom name="r_foot2" class="foot" pos="0.0379995 0.0548465  -0.0867505"/>
                  <geom name="r_foot3" class="foot" pos="0.0379995 0.0548465 0.129071"/>
                  <geom name="r_foot4" class="foot" pos="0.0379995  -0.0767345 0.129071"/>
                  <site name="right_foot" rgba="1 0 0 1" pos="0.035 0 0" euler="0 -1.571 0" size="0.01" group="1"/>
                </body>
              </body>
            </body>
          </body>
        </body>
      </body>
      <body name="neck" pos="-0.008 0 0.20825" quat="1.32679e-06 0 0 -1">
        <inertial pos="-0.000244686 -0.000118134 0.0329091" quat="0.998443 0.0557737 1.07166e-07 -1.91845e-06" mass="0.165011" diaginertia="6.78379e-05 5.68579e-05 3.82813e-05"/>
        <joint name="neck_yaw" pos="-0.008 0 0.20825" axis="0 0 1" limited="true" range="-3.14159 3.14159" class="MX64"/>
        <geom type="mesh" contype="0" conaffinity="0" group="1" density="0" rgba="0.286275 0.286275 0.286275 1" mesh="neck_visual"/>
        <geom size="0.0201 0.025 0.0314176" pos="-0.000244711 -0.00275529 0.0306824" type="box" rgba="0.286275 0.286275 0.286275 0"/>
        <body name="head" pos="-0.00024471 -0.000255294 0.0481" quat="0.499998 0.5 0.5 -0.500002">
          <inertial pos="-0.0665563 -0.0103216 -0.000100617" quat="0.999969 -0.000336797 -0.00449046 0.00648687" mass="0.473503" diaginertia="0.00196866 0.00145321 0.00107438"/>
          <joint name="head_pitch" pos="0 0 0" axis="0 0 1" limited="true" range="-3.14159 3.14159" class="MX64"/>
          <geom type="mesh" contype="0" conaffinity="0" group="1" density="0" rgba="0.286275 0.286275 0.286275 1" mesh="head_visual"/>
          <geom size="0.0811188 0.0778217 0.0788984" pos="-0.0659288 -0.00433207 -0.000205018" type="box" rgba="0.286275 0.286275 0.286275 0"/>
          <geom pos="-0.0648803 -0.0699522 -0.034205" quat="0.508649 0.508651 -0.491199 -0.491197" type="mesh" contype="0" conaffinity="0" group="1" density="0" rgba="0.615686 0.811765 0.929412 1" mesh="right_camera_visual"/>
          <geom size="5e-06 5.08174e-06 5e-06" pos="-0.0648853 -0.0699524 -0.034205" quat="0.508649 0.508651 -0.491199 -0.491197" type="box" rgba="0.615686 0.811765 0.929412 1"/>
          <camera name="egocentric" pos="0.01425 -0.019 0.04975" fovy="43.3" mode="fixed" euler="0.0 -1.570796 -1.570796"/>
        </body>
      </body>
      <body name="left_shoulder" pos="0 0.077 0.17725" quat="0.499998 -0.5 0.5 0.500002">
        <inertial pos="-3.61374e-05 -0.00254925 0.0287427" quat="0.618495 0.346197 0.615355 0.344891" mass="0.0845502" diaginertia="9.98768e-05 9.09162e-05 7.30289e-05"/>
        <joint name="left_shoulder_pitch" pos="0 0.0106 0.1616" axis="0 0 1" limited="true" range="-3.14159 3.14159" class="MX64"/>
        <geom type="mesh" contype="0" conaffinity="0" group="1" density="0" rgba="0.286275 0.286275 0.286275 1" mesh="left_shoulder_visual"/>
        <geom size="0.04 0.040721 0.0396866" pos="0 -0.000721047 0.0396866" type="box" rgba="0.286275 0.286275 0.286275 0"/>
        <body name="left_upper_arm" pos="0 -0.0100012 0.0479124" quat="0.499998 0.5 -0.500002 -0.5">
          <inertial pos="0.045902 0.000372495 9.27204e-06" quat="0.346504 0.576301 -0.375287 0.637943" mass="0.29923" diaginertia="0.00098868 0.000637586 0.000573833"/>
          <joint name="left_shoulder_roll" pos="0 0 0" axis="0 0 1" limited="true" range="-3.14159 3.14159" class="MX64"/>
          <geom type="mesh" contype="0" conaffinity="0" group="1" density="0" rgba="0.286275 0.286275 0.286275 1" mesh="left_upper_arm_visual"/>
          <geom size="0.112419 0.0395114 0.0447976" pos="0.0730323 -1.39214e-05 0.0106963" type="box" rgba="0.286275 0.286275 0.286275 0"/>
          <body name="left_lower_arm" pos="0.1575 -5.57465e-05 0.02695" quat="0.499998 -0.5 0.5 0.500002">
            <inertial pos="-0.000605553 -0.0509966 6.9181e-05" quat="0.568214 0.433479 -0.53189 0.454226" mass="0.287325" diaginertia="0.00115275 0.000789823 0.000530221"/>
            <joint name="left_elbow_pitch" pos="0 0 0" axis="0 0 1" limited="true" range="-3.14159 3.14159" class="MX64"/>
            <geom type="mesh" contype="0" conaffinity="0" group="1" density="0" rgba="0.286275 0.286275 0.286275 1" mesh="left_lower_arm_visual"/>
            <geom size="0.041286 0.129149 0.0254608" pos="-0.00247871 -0.0956493 -0.00252151" type="box" rgba="0.286275 0.286275 0.286275 0"/>
            <site name="left_hand" rgba="1 0 0 1" pos="-0.02 -0.14 0"/>
          </body>
        </body>
      </body>
      <body name="right_shoulder" pos="0 -0.077 0.17725" quat="0.499998 -0.5 0.5 0.500002">
        <inertial pos="-3.46247e-05 -0.00254925 -0.0287427" quat="0.346201 0.618498 0.344878 0.615357" mass="0.0845501" diaginertia="9.98771e-05 9.09162e-05 7.3029e-05"/>
        <joint name="right_shoulder_pitch" pos="0 -0.0106 0.1616" axis="0 0 1" limited="true" range="-3.14159 3.14159" class="MX64"/>
        <geom type="mesh" contype="0" conaffinity="0" group="1" density="0" rgba="0.286275 0.286275 0.286275 1" mesh="right_shoulder_visual"/>
        <geom size="0.04 0.0407336 0.0396809" pos="0 -0.000733595 -0.0396809" type="box" rgba="0.286275 0.286275 0.286275 0"/>
        <body name="right_upper_arm" pos="0 -0.0100012 -0.0479124" quat="0.499998 0.5 -0.500002 -0.5">
          <inertial pos="0.0458986 -0.000371241 0.000118834" quat="0.327762 0.587042 -0.375964 0.637656" mass="0.299218" diaginertia="0.000988599 0.000640993 0.000570263"/>
          <joint name="right_shoulder_roll" pos="0 0 0" axis="0 0 1" limited="true" range="-3.14159 3.14159" class="MX64"/>
          <geom type="mesh" contype="0" conaffinity="0" group="1" density="0" rgba="0.286275 0.286275 0.286275 1" mesh="right_upper_arm_visual"/>
          <geom size="0.112415 0.0395114 0.0447976" pos="0.0730282 1.39214e-05 0.0106963" type="box" rgba="0.286275 0.286275 0.286275 0"/>
          <body name="right_lower_arm" pos="0.1575 5.57465e-05 0.02695" quat="0.499998 -0.5 0.5 0.500002">
            <inertial pos="-0.00060488 -0.0510002 -6.85101e-05" quat="0.456626 0.549865 -0.476171 0.512252" mass="0.28735" diaginertia="0.00115298 0.000782489 0.000537795"/>
            <joint name="right_elbow_pitch" pos="0 0 0" axis="0 0 1" limited="true" range="-3.14159 3.14159" class="MX64"/>
            <geom type="mesh" contype="0" conaffinity="0" group="1" density="0" rgba="0.286275 0.286275 0.286275 1" mesh="right_lower_arm_visual"/>
            <geom size="0.041286 0.129159 0.0254784" pos="-0.00247871 -0.0956591 0.0025391" type="box" rgba="0.286275 0.286275 0.286275 0"/>
            <site name="right_hand" rgba="1 0 0 1" pos="-0.02 -0.14 0"/>
          </body>
        </body>
      </body>
    </body>
  </worldbody>

  <contact>
    <exclude body1="left_hip_yaw" body2="left_upper_leg"/>
    <exclude body1="right_hip_yaw" body2="right_upper_leg"/>
  </contact>

  <keyframe>
    <key name="stand_bent_knees"
      qpos="
        0.00000e+00  0.00000e+00  4.73774e-01  9.94428e-01  1.07808e-03
        1.04931e-01 -1.00319e-02  3.39000e-02  1.63000e-01 -9.04000e-01
        1.20000e+00 -5.10000e-01 -1.66000e-01 -3.29000e-02 -1.62000e-01
      -9.04000e-01  1.20000e+00 -5.08000e-01  1.67000e-01 -2.22000e-08
        6.45000e-05  1.71000e+00  1.97000e-01 -7.13000e-01  1.71000e+00
      -1.97000e-01 -7.18000e-01
      "
      ctrl="3.39000e-02  1.63000e-01 -9.04000e-01
        1.20000e+00 -5.10000e-01 -1.66000e-01 -3.29000e-02 -1.62000e-01
      -9.04000e-01  1.20000e+00 -5.08000e-01  1.67000e-01 -2.22000e-08
        6.45000e-05  1.71000e+00  1.97000e-01 -7.13000e-01  1.71000e+00
      -1.97000e-01 -7.18000e-01"
    />
  </keyframe>
</mujoco>
