<mujoco model="K1">
  <compiler angle="radian"/>

  <asset>
    <mesh name="Head_1" content_type="model/stl" file="meshes/Head_1.STL"/>
    <mesh name="Head_2" content_type="model/stl" file="meshes/Head_2.STL"/>
    <mesh name="Left_Arm_3" content_type="model/stl" file="meshes/Left_Arm_3.STL"/>
    <mesh name="Left_Arm_4" content_type="model/stl" file="meshes/Left_Arm_4.STL"/>
    <mesh name="Right_Arm_3" content_type="model/stl" file="meshes/Right_Arm_3.STL"/>
    <mesh name="Right_Arm_4" content_type="model/stl" file="meshes/Right_Arm_4.STL"/>
    <mesh name="Left_Foot" content_type="model/stl" file="meshes/Left_Foot.STL"/>
    <mesh name="Right_Foot" content_type="model/stl" file="meshes/Right_Foot.STL"/>
  </asset>

  <worldbody>
    <geom size="0.06 0.09 0.1" pos="0 0 0.1" type="box" rgba="0.792157 0.819608 0.933333 1"/>
    <geom size="0.05 0.05" pos="0 0 -0.06" quat="0.707105 0.707108 0 0" type="cylinder" rgba="0.792157 0.819608 0.933333 1"/>
    <body name="Head_1" pos="0.0056 0 0.2149">
      <inertial pos="-0.00069503 -0.00038527 0.031688" quat="0.993827 -0.00957801 0.00894723 -0.110168" mass="0.3" diaginertia="0.000429546 0.000420659 0.000125795"/>
      <joint name="AAHead_yaw" pos="0 0 0" axis="0 0 1" range="-1 1" actuatorfrcrange="-6 6"/>
      <geom type="mesh" rgba="0.75294 0.75294 0.75294 1" mesh="Head_1"/>
      <body name="Head_2" pos="0 0 0.033">
        <inertial pos="0.0110088 -0.000864606 0.0805424" quat="0.996554 -0.000898356 -0.0774465 -0.0296718" mass="0.701" diaginertia="0.00604512 0.00578769 0.00170607"/>
        <joint name="Head_pitch" pos="0 0 0" axis="0 1 0" range="-0.349 0.855" actuatorfrcrange="-6 6"/>
        <geom type="mesh" rgba="0.75294 0.75294 0.75294 1" mesh="Head_2"/>
        <!-- Camera NUbots frame (k): Hpk calibration from K1Sensors.yaml -->
        <site name="camera" pos="0.065  0.035 0.0915 " quat="0.52295637 -0.51398909 0.47576496 -0.48577726" size="0.01" rgba="1 0 0 1"/>
      </body>
    </body>
    <body name="Left_Arm_1" pos="0 0.077 0.1845">
      <inertial pos="-0.002701 0.062383 -0.011965" quat="0.578658 0.689818 -0.347436 0.261905" mass="0.5" diaginertia="0.00223871 0.00217107 0.000254225"/>
      <joint name="ALeft_Shoulder_Pitch" pos="0 0 0" axis="0 1 0" range="-3.316 1.22" actuatorfrcrange="-14 14"/>
      <body name="Left_Arm_2" pos="0.0025 0.068 -0.0135">
        <inertial pos="0.01729 0.018221 -4.329e-05" quat="0.413453 0.573635 -0.413453 0.573635" mass="0.09" diaginertia="0.000113 9.5e-05 6.5e-05"/>
        <joint name="Left_Shoulder_Roll" pos="0 0 0" axis="1 0 0" range="-1.74 1.57" actuatorfrcrange="-14 14"/>
        <geom size="0.035 0.034" pos="-0.007 0 0" quat="0.707105 0 0.707108 0" type="cylinder" rgba="0.75294 0.75294 0.75294 1"/>
        <body name="Left_Arm_3" pos="0 0.044428 0">
          <inertial pos="-0.0003979 0.072617 -0.00066218" quat="0.679502 0.689551 0.177403 -0.176989" mass="0.8" diaginertia="0.00606947 0.00606767 0.000385851"/>
          <joint name="Left_Elbow_Pitch" pos="0 0 0" axis="0 1 0" range="-2.27 2.27" actuatorfrcrange="-14 14"/>
          <geom type="mesh" rgba="0.75294 0.75294 0.75294 1" mesh="Left_Arm_3"/>
          <body name="left_hand_link" pos="0 0.1215 0">
            <inertial pos="-0.0015751 0.084637 0.0087033" quat="0.712106 0.700961 0.0264125 -0.0293496" mass="0.19" diaginertia="0.00205619 0.00202933 8.1482e-05"/>
            <joint name="Left_Elbow_Yaw" pos="0 0 0" axis="0 0 1" range="-2.44 0" actuatorfrcrange="-14 14"/>
            <geom type="mesh" rgba="0.75294 0.75294 0.75294 1" mesh="Left_Arm_4"/>
          </body>
        </body>
      </body>
    </body>
    <body name="Right_Arm_1" pos="0 -0.077 0.1845">
      <inertial pos="-0.0026302 -0.06251 -0.01199" quat="0.689302 0.577958 -0.263425 0.348475" mass="0.5" diaginertia="0.00224439 0.00217742 0.000255199"/>
      <joint name="ARight_Shoulder_Pitch" pos="0 0 0" axis="0 1 0" range="-3.316 1.22" actuatorfrcrange="-14 14"/>
      <body name="Right_Arm_2" pos="0.0025 -0.068 -0.0135">
        <inertial pos="0.017229 -0.018428 4.3784e-05" quat="0.573635 0.413453 -0.573635 0.413453" mass="0.09" diaginertia="0.000113 9.5e-05 6.5e-05"/>
        <joint name="Right_Shoulder_Roll" pos="0 0 0" axis="1 0 0" range="-1.57 1.74" actuatorfrcrange="-14 14"/>
        <geom size="0.035 0.034" pos="-0.007 0 0" quat="0.707105 0 0.707108 0" type="cylinder" rgba="0.75294 0.75294 0.75294 1"/>
        <body name="Right_Arm_3" pos="0 -0.044428 0">
          <inertial pos="-0.00039919 -0.072601 -0.00065629" quat="0.689551 0.679502 0.176989 -0.177403" mass="0.8" diaginertia="0.00607047 0.00606867 0.000386851"/>
          <joint name="Right_Elbow_Pitch" pos="0 0 0" axis="0 1 0" range="-2.27 2.27" actuatorfrcrange="-14 14"/>
          <geom type="mesh" rgba="0.75294 0.75294 0.75294 1" mesh="Right_Arm_3"/>
          <body name="right_hand_link" pos="0 -0.1215 0">
            <inertial pos="-0.0015177 -0.084536 0.0086733" quat="0.700925 0.712091 0.0296562 -0.0274245" mass="0.19" diaginertia="0.00205618 0.00203032 8.14943e-05"/>
            <joint name="Right_Elbow_Yaw" pos="0 0 0" axis="0 0 1" range="0 2.44" actuatorfrcrange="-14 14"/>
            <geom type="mesh" rgba="0.75294 0.75294 0.75294 1" mesh="Right_Arm_4"/>
          </body>
        </body>
      </body>
    </body>
    <body name="Left_Hip_Pitch" pos="0 0.096 -0.077">
      <inertial pos="-0.010093 -0.0019934 -0.024713" quat="0.704206 -0.178798 -0.198986 0.65767" mass="0.69" diaginertia="0.000987585 0.000880963 0.000503452"/>
      <joint name="Left_Hip_Pitch" pos="0 0 0" axis="0 1 0" range="-3 2.21" actuatorfrcrange="-30 30"/>
      <body name="Left_Hip_Roll" pos="0 0 -0.026">
        <inertial pos="0.023585 4.9e-05 -0.024996" quat="0.677218 0.203412 0.203412 0.677218" mass="0.13" diaginertia="0.000262 0.000222694 0.000118306"/>
        <joint name="Left_Hip_Roll" pos="0 0 0" axis="1 0 0" range="-0.4 1.57" actuatorfrcrange="-35 35"/>
        <geom size="0.036 0.047" quat="0.707105 0 0.707108 0" type="cylinder" rgba="0.75294 0.75294 0.75294 1"/>
        <body name="Left_Hip_Yaw" pos="0.012 0 -0.0485">
          <inertial pos="-0.0084744 -0.0040494 -0.087906" quat="0.857995 -0.00590801 -0.0582713 0.510308" mass="1.65" diaginertia="0.0162716 0.0158564 0.00134895"/>
          <joint name="Left_Hip_Yaw" pos="0 0 0" axis="0 0 1" range="-1 1" actuatorfrcrange="-20 20"/>
          <geom size="0.04 0.033" pos="0 0 -0.03" type="cylinder" rgba="0.75294 0.75294 0.75294 1"/>
          <body name="Left_Shank" pos="-0.014 0 -0.117">
            <inertial pos="-0.00081083 0.0031459 -0.10922" quat="0.940563 -0.00388906 -0.00385774 0.339574" mass="1.5" diaginertia="0.0237114 0.0236423 0.00123731"/>
            <joint name="Left_Knee_Pitch" pos="0 0 0" axis="0 1 0" range="0 2.23" actuatorfrcrange="-40 40"/>
            <geom size="0.045 0.035" quat="0.707105 0.707108 0 0" type="cylinder" rgba="0.75294 0.75294 0.75294 1"/>
            <geom size="0.03 0.03 0.05" pos="0 0 -0.13" type="box" rgba="0.75294 0.75294 0.75294 1"/>
            <body name="Left_Ankle_Cross" pos="0.00019706 0.0002 -0.24519">
              <inertial pos="0 0 0" quat="0.5 0.5 0.5 0.5" mass="0.039" diaginertia="4e-06 4e-06 2e-06"/>
              <joint name="Left_Ankle_Pitch" pos="0 0 0" axis="0 1 0" range="-0.87 0.345" actuatorfrcrange="-20 20"/>
              <body name="left_foot_link">
                <inertial pos="0.011662 0.000244 -0.014364" quat="-0.00144487 0.663983 -0.00148176 0.747745" mass="0.494" diaginertia="0.0012267 0.00117 0.000247305"/>
                <joint name="Left_Ankle_Roll" pos="0 0 0" axis="1 0 0" range="-0.345 0.345" actuatorfrcrange="-20 20"/>
                <geom type="mesh" rgba="0.75294 0.75294 0.75294 1" mesh="Left_Foot"/>
              </body>
            </body>
          </body>
        </body>
      </body>
    </body>
    <body name="Right_Hip_Pitch" pos="0 -0.096 -0.077">
      <inertial pos="-0.010065 0.0020086 -0.024739" quat="0.656712 -0.199052 -0.176963 0.705544" mass="0.69" diaginertia="0.000988671 0.000880749 0.00050458"/>
      <joint name="Right_Hip_Pitch" pos="0 0 0" axis="0 1 0" range="-3 2.21" actuatorfrcrange="-30 30"/>
      <body name="Right_Hip_Roll" pos="0 0 -0.026">
        <inertial pos="0.023585 4.9e-05 -0.024996" quat="0.677218 0.203412 0.203412 0.677218" mass="0.13" diaginertia="0.000262 0.000222694 0.000118306"/>
        <joint name="Right_Hip_Roll" pos="0 0 0" axis="1 0 0" range="-1.57 0.4" actuatorfrcrange="-35 35"/>
        <geom size="0.036 0.047" quat="0.707105 0 0.707108 0" type="cylinder" rgba="0.75294 0.75294 0.75294 1"/>
        <body name="Right_Hip_Yaw" pos="0.012 0 -0.0485">
          <inertial pos="-0.008475 0.0040392 -0.087906" quat="0.510308 -0.0582713 -0.00590801 0.857995" mass="1.65" diaginertia="0.0162716 0.0158564 0.00134895"/>
          <joint name="Right_Hip_Yaw" pos="0 0 0" axis="0 0 1" range="-1 1" actuatorfrcrange="-20 20"/>
          <geom size="0.04 0.033" pos="0 0 -0.03" type="cylinder" rgba="0.75294 0.75294 0.75294 1"/>
          <body name="Right_Shank" pos="-0.014 0 -0.117">
            <inertial pos="-0.000805 -0.003146 -0.109215" quat="0.940537 0.00388176 -0.00383651 -0.339646" mass="1.5" diaginertia="0.0237114 0.0236423 0.00123733"/>
            <joint name="Right_Knee_Pitch" pos="0 0 0" axis="0 1 0" range="0 2.23" actuatorfrcrange="-40 40"/>
            <geom size="0.045 0.035" quat="0.707105 0.707108 0 0" type="cylinder" rgba="0.75294 0.75294 0.75294 1"/>
            <geom size="0.03 0.03 0.05" pos="0 0 -0.13" type="box" rgba="0.75294 0.75294 0.75294 1"/>
            <body name="Right_Ankle_Cross" pos="0.00019706 -0.0002 -0.24519">
              <inertial pos="0 0 0" quat="0.5 0.5 0.5 0.5" mass="0.039" diaginertia="4e-06 4e-06 2e-06"/>
              <joint name="Right_Ankle_Pitch" pos="0 0 0" axis="0 1 0" range="-0.87 0.345" actuatorfrcrange="-20 20"/>
              <body name="right_foot_link">
                <inertial pos="0.011662 -0.000244 -0.014364" quat="0.00144487 0.663983 0.00148176 0.747745" mass="0.494" diaginertia="0.0012267 0.00117 0.000247305"/>
                <joint name="Right_Ankle_Roll" pos="0 0 0" axis="1 0 0" range="-0.345 0.345" actuatorfrcrange="-20 20"/>
                <geom type="mesh" rgba="0.75294 0.75294 0.75294 1" mesh="Right_Foot"/>
              </body>
            </body>
          </body>
        </body>
      </body>
    </body>
  </worldbody>
</mujoco>
