<robot name="onshape">
<link name="torso">
<visual>
<origin xyz="0 0 0" rpy="0 -0 0" />
<geometry>
<mesh filename="torso_visual.stl" />
</geometry>
<material name="torso_material">
<color rgba="0.286275 0.286275 0.286275 1.0" />
</material>
</visual>
<collision>
<origin xyz="0 0 0" rpy="0 -0 0" />
<geometry>
<mesh filename="torso_collision.stl" />
</geometry>
<material name="torso_material">
<color rgba="0.5 0.5 0.5 1.0" />
</material>
</collision>
<inertial>
<origin xyz="-0.000971341 -7.63301e-05 0.0898493" rpy="0 0 0" />
<mass value="1.83264" />
<inertia ixx="0.0154924" ixy="9.19136e-05" ixz="-0.00117023" iyy="0.0131549" iyz="2.21205e-06" izz="0.00592676" />
</inertial>
</link>

<link name="left_hip_yaw">
<visual>
<origin xyz="0 0 0" rpy="0 -0 0" />
<geometry>
<mesh filename="left_hip_yaw_visual.stl" />
</geometry>
<material name="left_hip_yaw_material">
<color rgba="0.286275 0.286275 0.286275 1.0" />
</material>
</visual>
<collision>
<origin xyz="0 0 0" rpy="0 -0 0" />
<geometry>
<mesh filename="left_hip_yaw_collision.stl" />
</geometry>
<material name="left_hip_yaw_material">
<color rgba="0.5 0.5 0.5 1.0" />
</material>
</collision>
<inertial>
<origin xyz="-0.0021828 -0.00894798 -0.0247563" rpy="0 0 0" />
<mass value="0.0594023" />
<inertia ixx="0.000118627" ixy="-4.66981e-07" ixz="-1.50388e-06" iyy="5.24124e-05" iyz="1.01414e-07" izz="0.000103641" />
</inertial>
</link>

<link name="left_hip_roll">
<visual>
<origin xyz="0 0 0" rpy="0 -0 0" />
<geometry>
<mesh filename="left_hip_roll_visual.stl" />
</geometry>
<material name="left_hip_roll_material">
<color rgba="0.286275 0.286275 0.286275 1.0" />
</material>
</visual>
<collision>
<origin xyz="0 0 0" rpy="0 -0 0" />
<geometry>
<mesh filename="left_hip_roll_collision.stl" />
</geometry>
<material name="left_hip_roll_material">
<color rgba="0.5 0.5 0.5 1.0" />
</material>
</collision>
<inertial>
<origin xyz="0.015733 -0.000686158 -0.0217073" rpy="0 0 0" />
<mass value="0.395953" />
<inertia ixx="0.000314298" ixy="1.5275e-09" ixz="9.78365e-18" iyy="0.000375808" iyz="5.62038e-06" izz="0.000127785" />
</inertial>
</link>

<link name="left_upper_leg">
<visual>
<origin xyz="0 0 0" rpy="0 -0 0" />
<geometry>
<mesh filename="left_upper_leg_visual.stl" />
</geometry>
<material name="left_upper_leg_material">
<color rgba="0.701961 0.701961 0.701961 1.0" />
</material>
</visual>
<collision>
<origin xyz="0 0 0" rpy="0 -0 0" />
<geometry>
<mesh filename="left_upper_leg_collision.stl" />
</geometry>
<material name="left_upper_leg_material">
<color rgba="0.5 0.5 0.5 1.0" />
</material>
</collision>
<inertial>
<origin xyz="0.0797922 0.0337121 -9.41261e-07" rpy="0 0 0" />
<mass value="0.136613" />
<inertia ixx="0.000145771" ixy="-4.01175e-05" ixz="1.28026e-08" iyy="0.000585265" iyz="-8.07276e-10" izz="0.000510087" />
</inertial>
</link>

<link name="left_lower_leg">
<visual>
<origin xyz="0 0 0" rpy="0 -0 0" />
<geometry>
<mesh filename="left_lower_leg_visual.stl" />
</geometry>
<material name="left_lower_leg_material">
<color rgba="0.737255 0.721569 0.717647 1.0" />
</material>
</visual>
<collision>
<origin xyz="0 0 0" rpy="0 -0 0" />
<geometry>
<mesh filename="left_lower_leg_collision.stl" />
</geometry>
<material name="left_lower_leg_material">
<color rgba="0.5 0.5 0.5 1.0" />
</material>
</collision>
<inertial>
<origin xyz="0.1001 0.00388186 -1.61259e-08" rpy="0 0 0" />
<mass value="0.0893011" />
<inertia ixx="9.01254e-05" ixy="1.57184e-09" ixz="-7.87158e-11" iyy="0.000408951" iyz="1.16101e-11" izz="0.0003363" />
</inertial>
</link>

<link name="left_ankle">
<visual>
<origin xyz="0 0 0" rpy="0 -0 0" />
<geometry>
<mesh filename="left_ankle_visual.stl" />
</geometry>
<material name="left_ankle_material">
<color rgba="0.286275 0.286275 0.286275 1.0" />
</material>
</visual>
<collision>
<origin xyz="0 0 0" rpy="0 -0 0" />
<geometry>
<mesh filename="left_ankle_collision.stl" />
</geometry>
<material name="left_ankle_material">
<color rgba="0.5 0.5 0.5 1.0" />
</material>
</collision>
<inertial>
<origin xyz="-0.015733 0.0219762 0.000512596" rpy="0 0 0" />
<mass value="0.329993" />
<inertia ixx="0.000265762" ixy="1.27304e-09" ixz="1.31968e-18" iyy="0.000157847" iyz="3.6829e-06" izz="0.000265677" />
</inertial>
</link>

<link name="left_foot">
<visual>
<origin xyz="0 0 0" rpy="0 -0 0" />
<geometry>
<mesh filename="left_foot_visual.stl" />
</geometry>
<material name="left_foot_material">
<color rgba="0.286275 0.286275 0.286275 1.0" />
</material>
</visual>
<collision>
<origin xyz="0 0 0" rpy="0 -0 0" />
<geometry>
<mesh filename="left_foot_collision.stl" />
</geometry>
<material name="left_foot_material">
<color rgba="0.5 0.5 0.5 1.0" />
</material>
</collision>
<inertial>
<origin xyz="0.0248226 0.00798542 0.033284" rpy="0 0 0" />
<mass value="0.245581" />
<inertia ixx="0.00134722" ixy="-9.73697e-06" ixz="2.7382e-08" iyy="0.00108383" iyz="-1.34065e-05" izz="0.000332029" />
</inertial>
</link>

<link name="left_foot_base">
<visual>
<origin xyz="0 0 0" rpy="0 -0 0" />
<geometry>
<mesh filename="left_foot_base_visual.stl" />
</geometry>
<material name="left_foot_base_material">
<color rgba="0.5 0.5 0.5 1.0" />
</material>
</visual>
<collision>
<origin xyz="0 0 0" rpy="0 -0 0" />
<geometry>
<mesh filename="left_foot_base_collision.stl" />
</geometry>
<material name="left_foot_base_material">
<color rgba="0.5 0.5 0.5 1.0" />
</material>
</collision>
<inertial>
<origin xyz="0 0 0" rpy="0 0 0" />
<mass value="0" />
<inertia ixx="0" ixy="0" ixz="0" iyy="0" iyz="0" izz="0" />
</inertial>
</link>

<joint name="left_foot_base" type="fixed">
<origin xyz="0.0360247 0 6.93889e-18" rpy="-1.71429e-29 -1.5708 0" />
<parent link="left_foot" />
<child link="left_foot_base" />
<axis xyz="0 0 1" />
<limit effort="1" velocity="20" />
<joint_properties friction="0.0" />
</joint>

<joint name="left_ankle_roll" type="revolute">
<origin xyz="0 0 6.93889e-18" rpy="1.5708 3.37316e-16 -3.88578e-16" />
<parent link="left_ankle" />
<child link="left_foot" />
<axis xyz="0 0 1" />
<limit effort="1" velocity="20" lower="-3.14159" upper="3.14159" />
<joint_properties friction="0.0" />
</joint>

<joint name="left_ankle_pitch" type="revolute">
<origin xyz="0.200203 -3.46945e-17 6.93889e-18" rpy="-3.05311e-15 5.55112e-17 -2.87748e-14" />
<parent link="left_lower_leg" />
<child link="left_ankle" />
<axis xyz="0 0 1" />
<limit effort="1" velocity="20" lower="-3.14159" upper="3.14159" />
<joint_properties friction="0.0" />
</joint>

<joint name="left_knee" type="revolute">
<origin xyz="0.206046 0.0569501 -1.44745e-14" rpy="-4.42146e-14 -3.94129e-15 -1.40554e-13" />
<parent link="left_upper_leg" />
<child link="left_lower_leg" />
<axis xyz="0 0 1" />
<limit effort="1" velocity="20" lower="-3.14159" upper="3.14159" />
<joint_properties friction="0.0" />
</joint>

<joint name="left_hip_pitch" type="revolute">
<origin xyz="0 -6.93889e-18 -1.38778e-17" rpy="-1.5708 -1.29896e-14 3.34849e-14" />
<parent link="left_hip_roll" />
<child link="left_upper_leg" />
<axis xyz="0 0 1" />
<limit effort="1" velocity="20" lower="-3.14159" upper="3.14159" />
<joint_properties friction="0.0" />
</joint>

<joint name="left_hip_roll" type="revolute">
<origin xyz="0.0221332 0 -0.0545" rpy="-4.55628e-30 1.5708 0" />
<parent link="left_hip_yaw" />
<child link="left_hip_roll" />
<axis xyz="0 0 1" />
<limit effort="1" velocity="20" lower="-3.14159" upper="3.14159" />
<joint_properties friction="0.0" />
</joint>

<joint name="left_hip_yaw" type="revolute">
<origin xyz="7.63278e-17 0.055 0" rpy="-5.43064e-25 -3.21985e-24 6.16346e-16" />
<parent link="torso" />
<child link="left_hip_yaw" />
<axis xyz="0 0 1" />
<limit effort="1" velocity="20" lower="-3.14159" upper="3.14159" />
<joint_properties friction="0.0" />
</joint>

<link name="right_hip_yaw">
<visual>
<origin xyz="0 0 0" rpy="0 -0 0" />
<geometry>
<mesh filename="right_hip_yaw_visual.stl" />
</geometry>
<material name="right_hip_yaw_material">
<color rgba="0.286275 0.286275 0.286275 1.0" />
</material>
</visual>
<collision>
<origin xyz="0 0 0" rpy="0 -0 0" />
<geometry>
<mesh filename="right_hip_yaw_collision.stl" />
</geometry>
<material name="right_hip_yaw_material">
<color rgba="0.5 0.5 0.5 1.0" />
</material>
</collision>
<inertial>
<origin xyz="-0.00218277 0.0089479 -0.0247564" rpy="0 0 0" />
<mass value="0.0594022" />
<inertia ixx="0.000118626" ixy="4.67163e-07" ixz="-1.50417e-06" iyy="5.24117e-05" iyz="-1.01073e-07" izz="0.000103641" />
</inertial>
</link>

<link name="right_hip_roll">
<visual>
<origin xyz="0 0 0" rpy="0 -0 0" />
<geometry>
<mesh filename="right_hip_roll_visual.stl" />
</geometry>
<material name="right_hip_roll_material">
<color rgba="0.286275 0.286275 0.286275 1.0" />
</material>
</visual>
<collision>
<origin xyz="0 0 0" rpy="0 -0 0" />
<geometry>
<mesh filename="right_hip_roll_collision.stl" />
</geometry>
<material name="right_hip_roll_material">
<color rgba="0.5 0.5 0.5 1.0" />
</material>
</collision>
<inertial>
<origin xyz="0.015733 -0.000232251 -0.0218286" rpy="0 0 0" />
<mass value="0.395953" />
<inertia ixx="0.000316367" ixy="-9.04561e-09" ixz="-5.97158e-20" iyy="0.000378025" iyz="1.97787e-06" izz="0.000127637" />
</inertial>
</link>

<link name="right_upper_leg">
<visual>
<origin xyz="0 0 0" rpy="0 -0 0" />
<geometry>
<mesh filename="right_upper_leg_visual.stl" />
</geometry>
<material name="right_upper_leg_material">
<color rgba="0.701961 0.701961 0.701961 1.0" />
</material>
</visual>
<collision>
<origin xyz="0 0 0" rpy="0 -0 0" />
<geometry>
<mesh filename="right_upper_leg_collision.stl" />
</geometry>
<material name="right_upper_leg_material">
<color rgba="0.5 0.5 0.5 1.0" />
</material>
</collision>
<inertial>
<origin xyz="0.0797922 0.0337121 -9.4141e-07" rpy="0 0 0" />
<mass value="0.136613" />
<inertia ixx="0.000145771" ixy="-4.01175e-05" ixz="1.28015e-08" iyy="0.000585265" iyz="-8.07034e-10" izz="0.000510087" />
</inertial>
</link>

<link name="right_lower_leg">
<visual>
<origin xyz="0 0 0" rpy="0 -0 0" />
<geometry>
<mesh filename="right_lower_leg_visual.stl" />
</geometry>
<material name="right_lower_leg_material">
<color rgba="0.737255 0.721569 0.717647 1.0" />
</material>
</visual>
<collision>
<origin xyz="0 0 0" rpy="0 -0 0" />
<geometry>
<mesh filename="right_lower_leg_collision.stl" />
</geometry>
<material name="right_lower_leg_material">
<color rgba="0.5 0.5 0.5 1.0" />
</material>
</collision>
<inertial>
<origin xyz="0.100103 0.00388186 1.61259e-08" rpy="0 0 0" />
<mass value="0.0893011" />
<inertia ixx="9.01254e-05" ixy="-1.57184e-09" ixz="-7.87158e-11" iyy="0.000408951" iyz="-1.16101e-11" izz="0.0003363" />
</inertial>
</link>

<link name="right_ankle">
<visual>
<origin xyz="0 0 0" rpy="0 -0 0" />
<geometry>
<mesh filename="right_ankle_visual.stl" />
</geometry>
<material name="right_ankle_material">
<color rgba="0.286275 0.286275 0.286275 1.0" />
</material>
</visual>
<collision>
<origin xyz="0 0 0" rpy="0 -0 0" />
<geometry>
<mesh filename="right_ankle_collision.stl" />
</geometry>
<material name="right_ankle_material">
<color rgba="0.5 0.5 0.5 1.0" />
</material>
</collision>
<inertial>
<origin xyz="-0.015733 0.0218226 0.000508968" rpy="0 0 0" />
<mass value="0.329993" />
<inertia ixx="0.000263648" ixy="7.53715e-09" ixz="2.47334e-19" iyy="0.000157848" iyz="3.69071e-06" izz="0.000263561" />
</inertial>
</link>

<link name="right_foot">
<visual>
<origin xyz="0 0 0" rpy="0 -0 0" />
<geometry>
<mesh filename="right_foot_visual.stl" />
</geometry>
<material name="right_foot_material">
<color rgba="0.286275 0.286275 0.286275 1.0" />
</material>
</visual>
<collision>
<origin xyz="0 0 0" rpy="0 -0 0" />
<geometry>
<mesh filename="right_foot_collision.stl" />
</geometry>
<material name="right_foot_material">
<color rgba="0.5 0.5 0.5 1.0" />
</material>
</collision>
<inertial>
<origin xyz="0.024823 -0.00798676 0.0332808" rpy="0 0 0" />
<mass value="0.245567" />
<inertia ixx="0.00134712" ixy="9.73589e-06" ixz="2.22656e-08" iyy="0.00108376" iyz="1.34039e-05" izz="0.000331997" />
</inertial>
</link>

<link name="right_foot_base">
<visual>
<origin xyz="0 0 0" rpy="0 -0 0" />
<geometry>
<mesh filename="right_foot_base_visual.stl" />
</geometry>
<material name="right_foot_base_material">
<color rgba="0.5 0.5 0.5 1.0" />
</material>
</visual>
<collision>
<origin xyz="0 0 0" rpy="0 -0 0" />
<geometry>
<mesh filename="right_foot_base_collision.stl" />
</geometry>
<material name="right_foot_base_material">
<color rgba="0.5 0.5 0.5 1.0" />
</material>
</collision>
<inertial>
<origin xyz="0 0 0" rpy="0 0 0" />
<mass value="0" />
<inertia ixx="0" ixy="0" ixz="0" iyy="0" iyz="0" izz="0" />
</inertial>
</link>

<joint name="right_foot_base" type="fixed">
<origin xyz="0.0360247 -1.38778e-17 0" rpy="-7.57306e-29 -1.5708 0" />
<parent link="right_foot" />
<child link="right_foot_base" />
<axis xyz="0 0 1" />
<limit effort="1" velocity="20" />
<joint_properties friction="0.0" />
</joint>

<joint name="right_ankle_roll" type="revolute">
<origin xyz="1.27676e-15 1.249e-16 -8.46545e-16" rpy="1.5708 -1.11022e-15 7.94382e-15" />
<parent link="right_ankle" />
<child link="right_foot" />
<axis xyz="0 0 1" />
<limit effort="1" velocity="20" lower="-3.14159" upper="3.14159" />
<joint_properties friction="0.0" />
</joint>

<joint name="right_ankle_pitch" type="revolute">
<origin xyz="0.200203 4.85723e-17 -6.93889e-18" rpy="1.88738e-15 -2.83277e-16 1.06524e-14" />
<parent link="right_lower_leg" />
<child link="right_ankle" />
<axis xyz="0 0 1" />
<limit effort="1" velocity="20" />
<joint_properties friction="0.0" />
</joint>

<joint name="right_knee" type="revolute">
<origin xyz="0.206046 0.0569501 -7.16788e-15" rpy="-7.0209e-15 3.9968e-14 -5.66214e-15" />
<parent link="right_upper_leg" />
<child link="right_lower_leg" />
<axis xyz="0 0 1" />
<limit effort="1" velocity="20" lower="-3.14159" upper="3.14159" />
<joint_properties friction="0.0" />
</joint>

<joint name="right_hip_pitch" type="revolute">
<origin xyz="-1.249e-16 0 3.81639e-17" rpy="-1.5708 -1.66533e-16 3.79139e-29" />
<parent link="right_hip_roll" />
<child link="right_upper_leg" />
<axis xyz="0 0 1" />
<limit effort="1" velocity="20" lower="-3.14159" upper="3.14159" />
<joint_properties friction="0.0" />
</joint>

<joint name="right_hip_roll" type="revolute">
<origin xyz="0.0221332 0 -0.0545" rpy="1.36238e-31 1.5708 0" />
<parent link="right_hip_yaw" />
<child link="right_hip_roll" />
<axis xyz="0 0 1" />
<limit effort="1" velocity="20" lower="-3.14159" upper="3.14159" />
<joint_properties friction="0.0" />
</joint>

<joint name="right_hip_yaw" type="revolute">
<origin xyz="-6.93889e-18 -0.055 -5.55112e-17" rpy="-1.44515e-26 2.05167e-26 2.3927e-15" />
<parent link="torso" />
<child link="right_hip_yaw" />
<axis xyz="0 0 1" />
<limit effort="1" velocity="20" lower="-3.14159" upper="3.14159" />
<joint_properties friction="0.0" />
</joint>

<link name="neck">
<visual>
<origin xyz="0 0 0" rpy="0 -0 0" />
<geometry>
<mesh filename="neck_visual.stl" />
</geometry>
<material name="neck_material">
<color rgba="0.5 0.5 0.5 1.0" />
</material>
</visual>
<collision>
<origin xyz="0 0 0" rpy="0 -0 0" />
<geometry>
<mesh filename="neck_collision.stl" />
</geometry>
<material name="neck_material">
<color rgba="0.5 0.5 0.5 1.0" />
</material>
</collision>
<inertial>
<origin xyz="0 0 0" rpy="0 0 0" />
<mass value="0" />
<inertia ixx="0" ixy="0" ixz="0" iyy="0" iyz="0" izz="0" />
</inertial>
</link>

<link name="head">
<visual>
<origin xyz="0 0 0" rpy="0 -0 0" />
<geometry>
<mesh filename="head_visual.stl" />
</geometry>
<material name="head_material">
<color rgba="0.281665 0.281665 0.281665 1.0" />
</material>
</visual>
<collision>
<origin xyz="0 0 0" rpy="0 -0 0" />
<geometry>
<mesh filename="head_collision.stl" />
</geometry>
<material name="head_material">
<color rgba="0.5 0.5 0.5 1.0" />
</material>
</collision>
<inertial>
<origin xyz="-0.0665563 0.0103216 0.000100617" rpy="0 0 0" />
<mass value="0.473503" />
<inertia ixx="0.0019685" ixy="-6.70055e-06" ixz="7.81948e-06" iyy="0.00145331" iyz="-5.39419e-07" izz="0.00107445" />
</inertial>
</link>

<link name="left_camera">
<visual>
<origin xyz="0 0 0" rpy="0 -0 0" />
<geometry>
<mesh filename="left_camera_visual.stl" />
</geometry>
<material name="left_camera_material">
<color rgba="0.5 0.5 0.5 1.0" />
</material>
</visual>
<collision>
<origin xyz="0 0 0" rpy="0 -0 0" />
<geometry>
<mesh filename="left_camera_collision.stl" />
</geometry>
<material name="left_camera_material">
<color rgba="0.5 0.5 0.5 1.0" />
</material>
</collision>
<inertial>
<origin xyz="0 0 0" rpy="0 0 0" />
<mass value="0" />
<inertia ixx="0" ixy="0" ixz="0" iyy="0" iyz="0" izz="0" />
</inertial>
</link>

<joint name="left_camera" type="fixed">
<origin xyz="-0.0648803 0.0699522 -0.033795" rpy="-1.5708 1.63801e-13 1.53589" />
<parent link="head" />
<child link="left_camera" />
<axis xyz="0 0 1" />
<limit effort="1" velocity="20" />
<joint_properties friction="0.0" />
</joint>

<link name="right_camera">
<visual>
<origin xyz="0 0 0" rpy="0 -0 0" />
<geometry>
<mesh filename="right_camera_visual.stl" />
</geometry>
<material name="right_camera_material">
<color rgba="0.5 0.5 0.5 1.0" />
</material>
</visual>
<collision>
<origin xyz="0 0 0" rpy="0 -0 0" />
<geometry>
<mesh filename="right_camera_collision.stl" />
</geometry>
<material name="right_camera_material">
<color rgba="0.5 0.5 0.5 1.0" />
</material>
</collision>
<inertial>
<origin xyz="0 0 0" rpy="0 0 0" />
<mass value="0" />
<inertia ixx="0" ixy="0" ixz="0" iyy="0" iyz="0" izz="0" />
</inertial>
</link>

<joint name="right_camera" type="fixed">
<origin xyz="-0.0648803 0.0699522 0.034205" rpy="-1.5708 1.63801e-13 1.53589" />
<parent link="head" />
<child link="right_camera" />
<axis xyz="0 0 1" />
<limit effort="1" velocity="20" />
<joint_properties friction="0.0" />
</joint>

<joint name="neck_pitch" type="revolute">
<origin xyz="-0.00024471 -0.000255294 0.0481" rpy="-1.5708 1.5708 0" />
<parent link="neck" />
<child link="head" />
<axis xyz="0 0 1" />
<limit effort="1" velocity="20" lower="-3.14159" upper="3.14159" />
<joint_properties friction="0.0" />
</joint>

<joint name="neck_yaw" type="revolute">
<origin xyz="-0.008 2.09034e-16 0.20825" rpy="-1.1045e-15 2.10942e-15 -3.14159" />
<parent link="torso" />
<child link="neck" />
<axis xyz="0 0 1" />
<limit effort="1" velocity="20" lower="-3.14159" upper="3.14159" />
<joint_properties friction="0.0" />
</joint>

<link name="left_shoulder">
<visual>
<origin xyz="0 0 0" rpy="0 -0 0" />
<geometry>
<mesh filename="left_shoulder_visual.stl" />
</geometry>
<material name="left_shoulder_material">
<color rgba="0.286275 0.286275 0.286275 1.0" />
</material>
</visual>
<collision>
<origin xyz="0 0 0" rpy="0 -0 0" />
<geometry>
<mesh filename="left_shoulder_collision.stl" />
</geometry>
<material name="left_shoulder_material">
<color rgba="0.5 0.5 0.5 1.0" />
</material>
</collision>
<inertial>
<origin xyz="-3.61374e-05 0.00254925 -0.0287427" rpy="0 0 0" />
<mass value="0.0845502" />
<inertia ixx="7.30295e-05" ixy="1.04146e-07" ixz="7.55192e-08" iyy="9.74311e-05" iyz="3.99116e-06" izz="9.33613e-05" />
</inertial>
</link>

<link name="left_upper_arm">
<visual>
<origin xyz="0 0 0" rpy="0 -0 0" />
<geometry>
<mesh filename="left_upper_arm_visual.stl" />
</geometry>
<material name="left_upper_arm_material">
<color rgba="0.286275 0.286275 0.286275 1.0" />
</material>
</visual>
<collision>
<origin xyz="0 0 0" rpy="0 -0 0" />
<geometry>
<mesh filename="left_upper_arm_collision.stl" />
</geometry>
<material name="left_upper_arm_material">
<color rgba="0.5 0.5 0.5 1.0" />
</material>
</collision>
<inertial>
<origin xyz="0.0836585 0.000830413 -0.000118056" rpy="0 0 0" />
<mass value="0.13422" />
<inertia ixx="0.000587833" ixy="3.04943e-05" ixz="-3.41697e-05" iyy="0.000173636" iyz="6.34845e-06" izz="0.000581601" />
</inertial>
</link>

<link name="left_lower_arm">
<visual>
<origin xyz="0 0 0" rpy="0 -0 0" />
<geometry>
<mesh filename="left_lower_arm_visual.stl" />
</geometry>
<material name="left_lower_arm_material">
<color rgba="0.286275 0.286275 0.286275 1.0" />
</material>
</visual>
<collision>
<origin xyz="0 0 0" rpy="0 -0 0" />
<geometry>
<mesh filename="left_lower_arm_collision.stl" />
</geometry>
<material name="left_lower_arm_material">
<color rgba="0.5 0.5 0.5 1.0" />
</material>
</collision>
<inertial>
<origin xyz="-0.000605553 0.0509966 -6.9181e-05" rpy="0 0 0" />
<mass value="0.287325" />
<inertia ixx="0.000778471" ixy="5.29345e-05" ixz="9.81492e-06" iyy="0.000543727" iyz="3.15618e-05" izz="0.0011506" />
</inertial>
</link>

<joint name="left_elbow_pitch" type="revolute">
<origin xyz="0.1575 -5.57465e-05 0.02695" rpy="1.5708 1.5708 0" />
<parent link="left_upper_arm" />
<child link="left_lower_arm" />
<axis xyz="0 0 1" />
<limit effort="1" velocity="20" lower="-3.14159" upper="3.14159" />
<joint_properties friction="0.0" />
</joint>

<joint name="left_shoulder_roll" type="revolute">
<origin xyz="0 0.0100012 -0.0479124" rpy="-1.5708 -3.06087e-14 1.5708" />
<parent link="left_shoulder" />
<child link="left_upper_arm" />
<axis xyz="0 0 1" />
<limit effort="1" velocity="20" lower="-3.14159" upper="3.14159" />
<joint_properties friction="0.0" />
</joint>

<joint name="left_shoulder_pitch" type="revolute">
<origin xyz="-5.659e-18 0.077 0.17725" rpy="1.5708 1.5708 0" />
<parent link="torso" />
<child link="left_shoulder" />
<axis xyz="0 0 1" />
<limit effort="1" velocity="20" lower="-3.14159" upper="3.14159" />
<joint_properties friction="0.0" />
</joint>

<link name="right_shoulder">
<visual>
<origin xyz="0 0 0" rpy="0 -0 0" />
<geometry>
<mesh filename="right_shoulder_visual.stl" />
</geometry>
<material name="right_shoulder_material">
<color rgba="0.286275 0.286275 0.286275 1.0" />
</material>
</visual>
<collision>
<origin xyz="0 0 0" rpy="0 -0 0" />
<geometry>
<mesh filename="right_shoulder_collision.stl" />
</geometry>
<material name="right_shoulder_material">
<color rgba="0.5 0.5 0.5 1.0" />
</material>
</collision>
<inertial>
<origin xyz="-3.46247e-05 0.00254925 0.0287427" rpy="0 0 0" />
<mass value="0.0845501" />
<inertia ixx="7.30296e-05" ixy="1.04639e-07" ixz="-7.5393e-08" iyy="9.74312e-05" iyz="-3.99136e-06" izz="9.33615e-05" />
</inertial>
</link>

<link name="right_upper_arm">
<visual>
<origin xyz="0 0 0" rpy="0 -0 0" />
<geometry>
<mesh filename="right_upper_arm_visual.stl" />
</geometry>
<material name="right_upper_arm_material">
<color rgba="0.286275 0.286275 0.286275 1.0" />
</material>
</visual>
<collision>
<origin xyz="0 0 0" rpy="0 -0 0" />
<geometry>
<mesh filename="right_upper_arm_collision.stl" />
</geometry>
<material name="right_upper_arm_material">
<color rgba="0.5 0.5 0.5 1.0" />
</material>
</collision>
<inertial>
<origin xyz="0.0836544 -0.000827717 0.000126203" rpy="0 0 0" />
<mass value="0.134208" />
<inertia ixx="0.000587789" ixy="2.7287e-05" ixz="-3.20481e-05" iyy="0.000173599" iyz="-6.38435e-06" izz="0.000581565" />
</inertial>
</link>

<link name="right_lower_arm">
<visual>
<origin xyz="0 0 0" rpy="0 -0 0" />
<geometry>
<mesh filename="right_lower_arm_visual.stl" />
</geometry>
<material name="right_lower_arm_material">
<color rgba="0.286275 0.286275 0.286275 1.0" />
</material>
</visual>
<collision>
<origin xyz="0 0 0" rpy="0 -0 0" />
<geometry>
<mesh filename="right_lower_arm_collision.stl" />
</geometry>
<material name="right_lower_arm_material">
<color rgba="0.5 0.5 0.5 1.0" />
</material>
</collision>
<inertial>
<origin xyz="-0.00060488 0.0510002 6.85101e-05" rpy="0 0 0" />
<mass value="0.28735" />
<inertia ixx="0.000778625" ixy="-3.06735e-05" ixz="1.1064e-05" iyy="0.000543818" iyz="-3.15336e-05" izz="0.00115082" />
</inertial>
</link>

<joint name="right_elbow_pitch" type="revolute">
<origin xyz="0.1575 5.57465e-05 0.02695" rpy="1.5708 1.5708 0" />
<parent link="right_upper_arm" />
<child link="right_lower_arm" />
<axis xyz="0 0 1" />
<limit effort="1" velocity="20" lower="-3.14159" upper="3.14159" />
<joint_properties friction="0.0" />
</joint>

<joint name="right_shoulder_roll" type="revolute">
<origin xyz="0 0.0100012 0.0479124" rpy="-1.5708 4.32987e-15 1.5708" />
<parent link="right_shoulder" />
<child link="right_upper_arm" />
<axis xyz="0 0 1" />
<limit effort="1" velocity="20" lower="-3.14159" upper="3.14159" />
<joint_properties friction="0.0" />
</joint>

<joint name="right_shoulder_pitch" type="revolute">
<origin xyz="-3.55526e-17 -0.077 0.17725" rpy="1.5708 1.5708 0" />
<parent link="torso" />
<child link="right_shoulder" />
<axis xyz="0 0 1" />
<limit effort="1" velocity="20" lower="-3.14159" upper="3.14159" />
<joint_properties friction="0.0" />
</joint>


</robot>
